import asyncio
import logging

import pytest
import requests

logger = logging.getLogger(__name__)


class TestErrorHandling:
    """Test error handling and recovery"""

    @pytest.mark.asyncio
    async def test_network_error_retry(self):
        """Test network error retry logic"""
        attempt_count = 0

        async def flaky_api_call():
            nonlocal attempt_count
            attempt_count += 1

            if attempt_count < 3:
                raise Exception("Network error")

            return {"success": True}

        # Retry logic
        max_retries = 3
        result = None
        for i in range(max_retries):
            try:
                result = await flaky_api_call()
                break
            except requests.exceptions.RequestException as exc:
                logger.warning(f"Network error on attempt {i+1}: {exc}")
                if i == max_retries - 1:
                    raise
                await asyncio.sleep(0.1 * (i + 1))  # Exponential backoff

        assert result["success"] is True
        assert attempt_count == 3

    def test_error_boundary(self):
        """Test error boundary catches errors"""

        # Mock error boundary
        class ErrorBoundary:
            def __init__(self):
                self.has_error = False
                self.error = None

            def catch_error(self, error):
                self.has_error = True
                self.error = error
                return "Fallback UI"

        boundary = ErrorBoundary()

        # Simulate error
        try:
            raise ValueError("Component error")
        except Exception as e:
            result = boundary.catch_error(e)

        assert boundary.has_error is True
        assert str(boundary.error) == "Component error"
        assert result == "Fallback UI"
